Workbook

Sheet ThamSo
A1: THAM SỐ – sửa ô chữ XANH (nền vàng = quan trọng). Mọi sheet khác tự tính lại.
A2: Giá vé bay/khách sạn là GIÁ THẬT tra Trip.com/Google Flights ngày 22/09/2026 qua trình duyệt (vượt tường bot). Sửa ô chữ XANH rồi mở lại bằng Excel/Google Sheets để tự tính. Tiền tệ: CNY, USD hoặc VND.
A3: Ngày bắt đầu tour (ngày bay) | B3: 46320 | D3: Đổi ngày này → toàn bộ lịch trình và deadline dời theo
A4: Tỷ giá CNY → VND | B4: 3950 | D4: VCB bán ra 19/09/2026: 3.947
A5: Tỷ giá USD → VND | B5: 26210 | D5: VCB bán ra 20/09/2026: 26.210
A6: Dự phòng (%) | B6: 0.1 | D6: Cộng thêm trên tổng chi phí mỗi nhóm
A8: Nhóm | B8: Số người | C8: Số phòng | D8: Cần visa TQ (1 = có, 0 = không) | E8: Ghi chú
A9: Hà Nội | B9: 2 | C9: 1 | D9: 1 | E9: Bay ZH104 HAN → SZX; về VJ7713 PKX → HAN
A10: Sài Gòn | B10: 4 | C10: 2 | D10: 1 | E10: Bay CZ8466 SGN → SZX; về VJ3949 PKX → SGN
A11: Quảng Châu | B11: 2 | C11: 1 | D11: 1 | E11: Tàu Guangzhou South → Futian; về cùng nhóm Sài Gòn VJ3949. Đặt 1 nếu cần visa
A12: Tổng số người | B12: =SUM(B9:B11) -> 8
A14: Khách sạn (phòng twin) | B14: Số đêm | C14: Giá / phòng / đêm (CNY) | D14: Khu | E14: Tham khảo 21/09
A15: Thâm Quyến | B15: 3 | C15: 350 | D15: Futian, cạnh Huaqiangbei / Coco Park | E15: Trip.com 22/09 (Futian, 3-4*): 7Days/RANZ ~280 CNY, Ji/Atour ~570-630; chọn ~350 dễ đạt
A16: Hàng Châu | B16: 3 | C16: 380 | D16: Hubin, bờ đông Tây Hồ | E16: Trip.com 22/09 (Hubin/Tây Hồ): Zprime 165, Haoyi 236, Mercure 289 CNY → 380 là dư
A17: Bắc Kinh | B17: 4 | C17: 400 | D17: Vương Phủ Tỉnh / Đông Đan | E17: Trip.com 22/09 (Vương Phủ Tỉnh): Zhong an ~298, UrCove Hyatt 574 CNY → 400 đạt, ở ngay VPT vẫn <=1,5tr
A18: Tổng số đêm | B18: =SUM(B15:B17) -> 10
A19: Số ngày tour (đêm + 1) | B19: =B18+1 -> 11
A20: Ngày kết thúc (ngày bay đêm) | B20: =B3+B18 -> 46330
A22: Vé máy bay / tàu (1 người, 1 chiều) | B22: Đơn giá | C22: Tiền tệ | D22: Chuyến | E22: Nguồn tham khảo 21/09
A23: HN đi | B23: 150 | C23: USD | D23: Shenzhen Airlines HAN 02:10 → SZX 05:00 (bay đêm, hội quân 26/10) | E23: Trip.com 22/09: rẻ nhất bay thẳng $150; ban ngày China Southern 16:10→19:00 $195
A24: SGN đi | B24: 73 | C24: USD | D24: Vietravel VU SGN 00:10 → SZX 04:00 (bay đêm rạng sáng 26/10) | E24: Trip.com 22/09: Vietravel $73 (rẻ nhất, hãng mới); CZ8466 ban ngày 14:30→18:15 $209
A25: QC đi (tàu) | B25: 74.5 | C25: CNY | D25: Tàu G Guangzhou South → Futian, 29 phút, hạng 2 | E25: Trip.com trains: 74,5 CNY hạng 2
A26: HN về | B26: 3196000 | C26: VND | D26: Air China PEK 00:10 → HAN 03:15 (bay thẳng ĐÊM, từ Bắc Kinh Thủ Đô PEK) | E26: Ảnh Sếp 23/09: 3.105.000đ; rẻ hơn Xiamen + bay đêm, giữ ngày cuối
A27: SGN + QC về | B27: 4164000 | C27: VND | D27: VJ3949 PKX 01:05 → SGN 05:00 (Vietjet, SGN + Quảng Châu về chung) | E27: Ảnh Sếp 23/09: VJ3949 4.126.000đ (từ PKX Đại Hưng)
A28: Hành lý ký gửi Vietjet 20 kg (nếu vé chưa kèm) | B28: 450000 | C28: VND | D28: Đặt 0 nếu vé đã tặng 20 kg (Vietjet 2026 tặng 20 kg tuyến quốc tế thẳng) | E28: Vietjet ~20–25k VND/kg mua online
A29: Bay SZX → HGH | B29: 597 | C29: CNY | D29: CZ8711 08:00 → 09:55 hoặc ZH 09:00 → 10:50, eco kèm 20 kg | E29: Trip.com 22/09: bay thẳng $90 (~597 CNY), China Southern 07:00→09:00 kèm 20kg
A30: Bay Hàng Châu → Bắc Kinh (~2h15) | B30: 520 | C30: CNY | D30: Bay HGH → Bắc Kinh (China Eastern ~2h15), THAY tàu; + transfer sân bay ~1h | E30: Trip.com 23/09: bay thẳng 480–560 CNY, rẻ & nhanh hơn tàu 650
A32: Vé tham quan (CNY / người) | B32: Giá | C32: Tính vào chi phí (1/0) | D32: Ngày dùng | E32: Nguồn 2026
A33: Ping An Free Sky (vé online) | B33: 180 | C33: 1 | D33: Ngày 2 | E33: eastchinatrip: online 180, quầy 200
A34: Thuyền Tây Hồ + đảo Tiểu Doanh | B34: 55 | C34: 1 | D34: Ngày 4 | E34: chinadiscovery: 55 thuyền thường / 70 thuyền hoa
A35: Tháp Lôi Phong | B35: 40 | C35: 1 | D35: Ngày 4 | E35: travelchinawith.me
A36: Impression West Lake (vé thường) | B36: 360 | C36: 1 | D36: Ngày 4 | E36: chinadiscovery: 360 / 430 VIP / 960 premium
A37: Linh Ẩn + Phi Lai Phong (combo) | B37: 75 | C37: 1 | D37: Ngày 5 | E37: GetYourGuide / Trip.com: 45 + 30
A38: Mutianyu vé cửa | B38: 45 | C38: 1 | D38: Ngày 7 | E38: greatwalltravelguide 2026
A39: Mutianyu shuttle bus | B39: 15 | C39: 1 | D39: Ngày 7 | E39: discoverchinatours: 15 khứ hồi
A40: Mutianyu cáp treo / ghế treo + máng trượt (khứ hồi) | B40: 140 | C40: 1 | D40: Ngày 7 | E40: greatwalltravelguide: 140 khứ hồi, 100 một chiều
A41: Thiên Đàn vé thông (mùa thấp điểm) | B41: 28 | C41: 1 | D41: Ngày 8 | E41: intotravelchina 2026
A42: Ditan Park (ngân hạnh) | B42: 10 | C42: 1 | D42: Ngày 8 | E42: visitbeijing
A43: Di Hòa Viên vé thông (mùa thấp điểm) | B43: 50 | C43: 1 | D43: Ngày 8 | E43: dragontrail 2026
A44: Hương Sơn (tuỳ chọn) | B44: 15 | C44: 0 | D44: Ngày 8 | E44: Đặt 1 nếu đi; cuối tuần 1–2/11 rất đông
...

Sheet TongHop
A1: TỔNG HỢP CHI PHÍ (VND) – tự tính từ 3 sheet ChiPhi
A3: Nhóm | B3: Số người | C3: / người | D3: / người có dự phòng | E3: Cả nhóm | F3: Cả nhóm có dự phòng
A4: Hà Nội | B4: =ThamSo!$B$9 -> 2 | C4: =ChiPhi_HN!$D$23 -> 38076820 | D4: =ChiPhi_HN!$D$25 -> 41884502 | E4: =ChiPhi_HN!$E$23 -> 76153640 | F4: =ChiPhi_HN!$E$25 -> 83769004
A5: Sài Gòn | B5: =ThamSo!$B$10 -> 4 | C5: =ChiPhi_SGN!$D$23 -> 37026650 | D5: =ChiPhi_SGN!$D$25 -> 40729315 | E5: =ChiPhi_SGN!$E$23 -> 148106600 | F5: =ChiPhi_SGN!$E$25 -> 162917260
A6: Quảng Châu | B6: =ThamSo!$B$11 -> 2 | C6: =ChiPhi_QC!$D$23 -> 35407595 | D6: =ChiPhi_QC!$D$25 -> 38948354 | E6: =ChiPhi_QC!$E$23 -> 70815190 | F6: =ChiPhi_QC!$E$25 -> 77896709
A7: CẢ ĐOÀN | B7: =SUM(B4:B6) -> 8 | E7: =SUM(E4:E6) | F7: =SUM(F4:F6) -> 324582973
A9: Ngày đi | B9: =ThamSo!$B$3 -> 46320
A10: Ngày bay về (đêm) | B10: =ThamSo!$B$20 -> 46330
A11: Số ngày / đêm | B11: =ThamSo!$B$19&" ngày / "&ThamSo!$B$18&" đêm" -> 11 ngày / 10 đêm
A13: Chú giải
A14: Chữ xanh dương = ô nhập tay (chỉ ở sheet ThamSo). Chữ xanh lá = lấy từ sheet khác. Chữ đen = công thức. Nền vàng = ô quan trọng.

Sheet LichTrinh
A1: LỊCH TRÌNH – ngày tự dời theo ThamSo!B3. [trend] = điểm hot với dân du lịch trẻ 2025–2026.
A2: ⚠️ Giờ-by-giờ dưới là bản HOẠT ĐỘNG gốc (v3: đáp ban NGÀY, Thâm Quyến 3 / Hàng Châu 2 / Bắc Kinh 4). THỰC TẾ đã đổi: vé bay ĐÊM (SGN Vietravel 00:10→04:00, HN Shenzhen Air 02:10→05:00), HỘI QUÂN sáng 26/10, HN VỀ ban ngày XiamenAir (đêm 03→04/11 không có VietJet thẳng). Sau khi CHỐT option (A=TQ2/HC3/BK4, B=v3, C=TQ3/HC3/BK4) sẽ sắp lại thứ tự ngày cho khớp số đêm. Xem file .md mục 2–4 cho bản cập nhật.
A3: Ngày | B3: Ngày tháng | C3: Thứ | D3: Thành phố | E3: Giờ | F3: Hoạt động | G3: Vé (CNY) | H3: Ghi chú
A4: Ngày 1 | B4: =ThamSo!$B$3+0 -> 46320 | C4: =CHOOSE(WEEKDAY(B4),"CN","T2","T3","T4","T5","T6","T7") -> CN | D4: Thâm Quyến | E4: 12:00 / 12:30 | F4: Nhóm SGN có mặt Tân Sơn Nhất T2, nhóm HN có mặt Nội Bài T2 | H4: Trước giờ bay 2h30
A5: Ngày 1 | B5: =ThamSo!$B$3+0 -> 46320 | C5: =CHOOSE(WEEKDAY(B5),"CN","T2","T3","T4","T5","T6","T7") -> CN | E5: 17:50 / 18:20 | F5: Đáp SZX T3 (ZH104 / CZ8466). Nhập cảnh, lấy hành lý, gặp nhau sảnh đến | H5: Cùng nhà ga T3
A6: Ngày 1 | B6: =ThamSo!$B$3+0 -> 46320 | C6: =CHOOSE(WEEKDAY(B6),"CN","T2","T3","T4","T5","T6","T7") -> CN | E6: 19:30 | F6: Về khách sạn Futian: Metro L11 ~30 phút (~8 CNY) hoặc 2 xe Didi (~100 CNY/xe)
A7: Ngày 1 | B7: =ThamSo!$B$3+0 -> 46320 | C7: =CHOOSE(WEEKDAY(B7),"CN","T2","T3","T4","T5","T6","T7") -> CN | E7: 19:30–20:00 | F7: Nhóm Quảng Châu: tàu G Guangzhou South → Futian (29 phút), về khách sạn | H7: Vé 74,5 CNY
A8: Ngày 1 | B8: =ThamSo!$B$3+0 -> 46320 | C8: =CHOOSE(WEEKDAY(B8),"CN","T2","T3","T4","T5","T6","T7") -> CN | E8: 20:00 | F8: Cả đoàn ăn tối Coco Park. Kích hoạt eSIM, set Alipay / WeChat Pay
A9: Ngày 2 | B9: =ThamSo!$B$3+1 -> 46321 | C9: =CHOOSE(WEEKDAY(B9),"CN","T2","T3","T4","T5","T6","T7") -> T2 | D9: Thâm Quyến | E9: 09:30–12:30 | F9: [trend] Nantou Ancient Town – cổ thành 1.700 năm cải tạo thành khu cafe, gallery, bar thủ công (Metro L12). Ăn trưa trong khu | H9: Miễn phí
A10: Ngày 2 | B10: =ThamSo!$B$3+1 -> 46321 | C10: =CHOOSE(WEEKDAY(B10),"CN","T2","T3","T4","T5","T6","T7") -> T2 | E10: 14:00–16:30 | F10: Huaqiangbei – chợ điện tử lớn nhất TQ: SEG Plaza, Huaqiang Electronic World, Mingtong | H10: Miễn phí, mở ~10:00–20:00
A11: Ngày 2 | B11: =ThamSo!$B$3+1 -> 46321 | C11: =CHOOSE(WEEKDAY(B11),"CN","T2","T3","T4","T5","T6","T7") -> T2 | E11: 17:00–19:00 | F11: Ping An Finance Center – Free Sky tầng 116, hoàng hôn ~17:50 (vào cửa cuối 19:15, book bằng hộ chiếu) | G11: =ThamSo!$B$33*ThamSo!$C$33 -> 180 | H11: Online 180, quầy 200
A12: Ngày 2 | B12: =ThamSo!$B$3+1 -> 46321 | C12: =CHOOSE(WEEKDAY(B12),"CN","T2","T3","T4","T5","T6","T7") -> T2 | E12: 19:30 | F12: Ăn tối Futian
A13: Ngày 3 | B13: =ThamSo!$B$3+2 -> 46322 | C13: =CHOOSE(WEEKDAY(B13),"CN","T2","T3","T4","T5","T6","T7") -> T3 | D13: Thâm Quyến | E13: 09:00–12:00 | F13: Dafen Oil Painting Village – làng tranh sơn dầu, đặt vẽ / mua tranh giá xưởng (Metro L3 ga Dafen, exit A1) | H13: Miễn phí
A14: Ngày 3 | B14: =ThamSo!$B$3+2 -> 46322 | C14: =CHOOSE(WEEKDAY(B14),"CN","T2","T3","T4","T5","T6","T7") -> T3 | E14: 14:00–16:00 | F14: [trend] Shenzhen MixC World (Nam Sơn) – flagship Huawei, HAUS NOWHERE, cafe; hoặc OCT-LOFT nếu thích nghệ thuật | H14: Miễn phí
A15: Ngày 3 | B15: =ThamSo!$B$3+2 -> 46322 | C15: =CHOOSE(WEEKDAY(B15),"CN","T2","T3","T4","T5","T6","T7") -> T3 | E15: 16:30–18:30 | F15: [trend] Shenzhen Talent Park / Shenzhen Bay Park – hoàng hôn, skyline Hong Kong | H15: Miễn phí
A16: Ngày 3 | B16: =ThamSo!$B$3+2 -> 46322 | C16: =CHOOSE(WEEKDAY(B16),"CN","T2","T3","T4","T5","T6","T7") -> T3 | E16: 19:00 | F16: Ăn tối Sea World (Shekou). Soạn hành lý bay sớm
A17: Ngày 4 | B17: =ThamSo!$B$3+3 -> 46323 | C17: =CHOOSE(WEEKDAY(B17),"CN","T2","T3","T4","T5","T6","T7") -> T4 | D17: Hàng Châu | E17: 05:45 | F17: Rời khách sạn ra SZX (30–40 phút)
A18: Ngày 4 | B18: =ThamSo!$B$3+3 -> 46323 | C18: =CHOOSE(WEEKDAY(B18),"CN","T2","T3","T4","T5","T6","T7") -> T4 | E18: 08:00 → 09:55 | F18: Bay SZX → HGH (CZ8711 hoặc chuyến tương đương) | H18: ThamSo dòng 29
A19: Ngày 4 | B19: =ThamSo!$B$3+3 -> 46323 | C19: =CHOOSE(WEEKDAY(B19),"CN","T2","T3","T4","T5","T6","T7") -> T4 | E19: 10:30–11:30 | F19: HGH → khách sạn khu Hubin (Metro L1/L7 ~1h hoặc taxi ~50 phút). Gửi hành lý
A20: Ngày 4 | B20: =ThamSo!$B$3+3 -> 46323 | C20: =CHOOSE(WEEKDAY(B20),"CN","T2","T3","T4","T5","T6","T7") -> T4 | E20: 12:00 | F20: Ăn trưa gần Hubin: cá giấm Tây Hồ, thịt Đông Pha
A21: Ngày 4 | B21: =ThamSo!$B$3+3 -> 46323 | C21: =CHOOSE(WEEKDAY(B21),"CN","T2","T3","T4","T5","T6","T7") -> T4 | E21: 13:30–17:30 | F21: Tây Hồ: thuyền ra đảo Tiểu Doanh (chuyến cuối 16:00) → đê Tô → tháp Lôi Phong ngắm hoàng hôn | G21: =ThamSo!$B$34*ThamSo!$C$34 -> 55 | H21: Lôi Phong tính dòng dưới
A22: Ngày 4 | B22: =ThamSo!$B$3+3 -> 46323 | C22: =CHOOSE(WEEKDAY(B22),"CN","T2","T3","T4","T5","T6","T7") -> T4 | F22: Tháp Lôi Phong | G22: =ThamSo!$B$35*ThamSo!$C$35 -> 40 | H22: Mùa 11–3 mở tới 17:30
A23: Ngày 4 | B23: =ThamSo!$B$3+3 -> 46323 | C23: =CHOOSE(WEEKDAY(B23),"CN","T2","T3","T4","T5","T6","T7") -> T4 | E23: 19:40–20:35 | F23: [trend] Impression West Lake – show Trương Nghệ Mưu trên mặt hồ (82 Beishan Rd). Đặt trước 1–2 tuần | G23: =ThamSo!$B$36*ThamSo!$C$36 -> 360 | H23: 360 / 430 VIP / 960
A24: Ngày 5 | B24: =ThamSo!$B$3+4 -> 46324 | C24: =CHOOSE(WEEKDAY(B24),"CN","T2","T3","T4","T5","T6","T7") -> T5 | D24: Hàng Châu | E24: 08:00–10:30 | F24: Chùa Linh Ẩn + Phi Lai Phong, đi sớm tránh đông | G24: =ThamSo!$B$37*ThamSo!$C$37 -> 75 | H24: 45 + 30
A25: Ngày 5 | B25: =ThamSo!$B$3+4 -> 46324 | C25: =CHOOSE(WEEKDAY(B25),"CN","T2","T3","T4","T5","T6","T7") -> T5 | E25: 11:00–14:00 | F25: [trend] Làng trà Long Tỉnh + Mãn Giác Lũng – cafe giữa đồi trà, mùa hoa quế. Ăn trưa nhà dân trồng trà | H25: Ăn ~80–120 CNY
A26: Ngày 5 | B26: =ThamSo!$B$3+4 -> 46324 | C26: =CHOOSE(WEEKDAY(B26),"CN","T2","T3","T4","T5","T6","T7") -> T5 | E26: 14:30–16:00 | F26: Bảo tàng Trà quốc gia (nghỉ Thứ Hai) | H26: Miễn phí
A27: Ngày 5 | B27: =ThamSo!$B$3+4 -> 46324 | C27: =CHOOSE(WEEKDAY(B27),"CN","T2","T3","T4","T5","T6","T7") -> T5 | E27: 16:30–18:00 | F27: Cửu Khê (Jiuxi) đi bộ suối giữa rừng trà | H27: Miễn phí
A28: Ngày 5 | B28: =ThamSo!$B$3+4 -> 46324 | C28: =CHOOSE(WEEKDAY(B28),"CN","T2","T3","T4","T5","T6","T7") -> T5 | E28: 18:30–21:00 | F28: [trend] Chợ đêm Wulin (17:00–23:00) + đường Wulin; hoặc phố cổ Hà Phường
A29: Ngày 6 | B29: =ThamSo!$B$3+5 -> 46325 | C29: =CHOOSE(WEEKDAY(B29),"CN","T2","T3","T4","T5","T6","T7") -> T6 | D29: Hàng Châu → Bắc Kinh | E29: 09:00–11:00 | F29: [trend] Xiaohe Street + cầu Gongchen (Đại Vận Hà) – phố cổ ven kênh, cafe, shop thủ công | H29: Miễn phí; trả phòng / gửi hành lý trước
A30: Ngày 6 | B30: =ThamSo!$B$3+5 -> 46325 | C30: =CHOOSE(WEEKDAY(B30),"CN","T2","T3","T4","T5","T6","T7") -> T6 | E30: 11:30 | F30: Ra ga Hangzhou East (Metro L1/L4 ~30 phút)
A31: Ngày 6 | B31: =ThamSo!$B$3+5 -> 46325 | C31: =CHOOSE(WEEKDAY(B31),"CN","T2","T3","T4","T5","T6","T7") -> T6 | E31: 12:00–13:30 | F31: Tàu G Hangzhou East → Beijing South hạng 2, chọn chuyến ~4,5h | H31: ThamSo dòng 30; mở bán 15 ngày trước
A32: Ngày 6 | B32: =ThamSo!$B$3+5 -> 46325 | C32: =CHOOSE(WEEKDAY(B32),"CN","T2","T3","T4","T5","T6","T7") -> T6 | E32: ~17:30–18:30 | F32: Đến Beijing South → khách sạn Vương Phủ Tỉnh / Đông Đan (2 xe Didi ~40 CNY/xe)
A33: Ngày 6 | B33: =ThamSo!$B$3+5 -> 46325 | C33: =CHOOSE(WEEKDAY(B33),"CN","T2","T3","T4","T5","T6","T7") -> T6 | E33: 19:30 | F33: Vịt quay Siji Minfu 四季民福 gần Tử Cấm Thành (150–200 CNY/người), đặt bàn hoặc tới sớm | H33: Tính trong ăn uống
A34: Ngày 7 | B34: =ThamSo!$B$3+6 -> 46326 | C34: =CHOOSE(WEEKDAY(B34),"CN","T2","T3","T4","T5","T6","T7") -> T7 | D34: Bắc Kinh | E34: 07:00 | F34: Xe riêng 14 chỗ đi Mutianyu (~1h30), đi sớm vì Thứ Bảy đông | H34: ThamSo dòng xe
A35: Ngày 7 | B35: =ThamSo!$B$3+6 -> 46326 | C35: =CHOOSE(WEEKDAY(B35),"CN","T2","T3","T4","T5","T6","T7") -> T7 | E35: 08:45–12:30 | F35: Vạn Lý Trường Thành Mộ Điền Dục: cáp treo lên tháp 14, đi bộ tới tháp 20, máng trượt xuống (tuỳ thời tiết, không cho 60+) | G35: =ThamSo!$B$38*ThamSo!$C$38 -> 45 | H35: + shuttle 15 + cáp/máng 140
A36: Ngày 7 | B36: =ThamSo!$B$3+6 -> 46326 | C36: =CHOOSE(WEEKDAY(B36),"CN","T2","T3","T4","T5","T6","T7") -> T7 | F36: Shuttle bus bãi xe ↔ cổng | G36: =ThamSo!$B$39*ThamSo!$C$39 -> 15
A37: Ngày 7 | B37: =ThamSo!$B$3+6 -> 46326 | C37: =CHOOSE(WEEKDAY(B37),"CN","T2","T3","T4","T5","T6","T7") -> T7 | F37: Cáp treo / ghế treo + máng trượt khứ hồi | G37: =ThamSo!$B$40*ThamSo!$C$40 -> 140 | H37: Một chiều 100
A38: Ngày 7 | B38: =ThamSo!$B$3+6 -> 46326 | C38: =CHOOSE(WEEKDAY(B38),"CN","T2","T3","T4","T5","T6","T7") -> T7 | E38: 12:30 | F38: Ăn trưa chân núi
A39: Ngày 7 | B39: =ThamSo!$B$3+6 -> 46326 | C39: =CHOOSE(WEEKDAY(B39),"CN","T2","T3","T4","T5","T6","T7") -> T7 | E39: 15:30–17:30 | F39: [trend] 798 Art Zone – trên đường về từ Mutianyu, gallery mở Thứ Bảy, street art | H39: Miễn phí
A40: Ngày 7 | B40: =ThamSo!$B$3+6 -> 46326 | C40: =CHOOSE(WEEKDAY(B40),"CN","T2","T3","T4","T5","T6","T7") -> T7 | E40: 18:00–19:00 | F40: Tuỳ chọn: Công viên Olympic – Tổ Chim, Water Cube lên đèn (ngắm ngoài) | H40: Miễn phí
...

Sheet Deadline
A1: DEADLINE ĐẶT VÉ – tự dời theo ThamSo!B3
A3: Việc | B3: Ngày dùng | C3: Deadline | D3: Cách làm | E3: Ghi chú
A4: Visa TQ loại L (nhóm cần visa) | B4: =ThamSo!$B$3 -> 46320 | C4: =ThamSo!$B$3-15 -> 46305 | D4: Form visaforchina.cn → nộp CVASC Hà Nội (Trang An Complex, Phùng Chí Kiên) / TP.HCM (Saigon Trade Center, Tôn Đức Thắng), sáng ngày làm việc | E4: ~4 ngày làm việc
A5: Vé quốc tế đi + về, khách sạn | B5: =ThamSo!$B$3 -> 46320 | C5: =TODAY() -> 46288 | D5: Web hãng / Trip.com / Agoda; lọc khách sạn nhận khách nước ngoài, huỷ miễn phí | E5: Ngay khi chốt
A6: Vé tàu Guangzhou South → Futian | B6: =ThamSo!$B$3+0 -> 46320 | C6: =ThamSo!$B$3+0-14 -> 46306 | D6: 12306 (mở bán 15 ngày trước) | E6: Nhóm Quảng Châu
A7: Ping An Free Sky | B7: =ThamSo!$B$3+1 -> 46321 | C7: =ThamSo!$B$3+1-1 -> 46320 | D7: Trip.com / Klook
A8: Impression West Lake | B8: =ThamSo!$B$3+3 -> 46323 | C8: =ThamSo!$B$3+3-14 -> 46309 | D8: Trip.com / Klook / gotohangzhou.com | E8: Hay cháy vé
A9: Tàu Hangzhou East → Beijing South | B9: =ThamSo!$B$3+5 -> 46325 | C9: =ThamSo!$B$3+5-14 -> 46311 | D9: 12306 bằng hộ chiếu, hoặc Trip.com pre-order | E9: Mở bán 15 ngày trước
A10: Thiên An Môn (mở đặt từ) | B10: =ThamSo!$B$3+9 -> 46329 | C10: =ThamSo!$B$3+9-9 -> 46320 | D10: WeChat mini-program 天安门广场预约参观 (1–9 ngày trước) | E10: Miễn phí, hộ chiếu gốc
A11: Tử Cấm Thành (mở bán 20:00 giờ Bắc Kinh) | B11: =ThamSo!$B$3+9 -> 46329 | C11: =ThamSo!$B$3+9-7 -> 46322 | D11: WeChat mini-program 故宫博物院 / web Palace Museum; 1 vé/hộ chiếu, slot sáng | E11: 19:00 giờ VN
A12: Mutianyu + xe 14 chỗ | B12: =ThamSo!$B$3+6 -> 46326 | C12: =ThamSo!$B$3+6-7 -> 46319 | D12: Trip.com / en.mutianyugreatwall.com; xe qua Klook / TravelChinaGuide | E12: Hộ chiếu đúng tên
A13: Ung Hòa Cung (slot giờ) | B13: =ThamSo!$B$3+8 -> 46328 | C13: =ThamSo!$B$3+8-3 -> 46325 | D13: Đặt online, bắt buộc từ 2026

Sheet ChiPhi_HN
A1: CHI PHÍ DỰ KIẾN – nhóm HN (VND). Toàn bộ là công thức, sửa ở sheet ThamSo.
A2: Số người | B2: =ThamSo!$B$9 -> 2
A3: Số phòng | B3: =ThamSo!$C$9 -> 1
A4: Cần visa (1/0) | B4: =ThamSo!$D$9 -> 1
A6: Khoản | B6: Số lượng | C6: Đơn giá (VND) | D6: Thành tiền / người (VND) | E6: Cả nhóm (VND) | F6: Cách tính / ghi chú
A7: Visa Trung Quốc loại L | B7: =$B$4 -> 1 | C7: =ThamSo!$B$59*ThamSo!$B$5+ThamSo!$B$60 -> 2257600 | D7: =B7*C7 -> 2257600 | E7: =D7*$B$2 -> 4515200 | F7: Phí lãnh sự (USD) + phí dịch vụ CVASC; = 0 nếu nhóm không cần visa
A8: Vé đi (tới Thâm Quyến) | B8: 1 | C8: =IF(ThamSo!$C$23="CNY",ThamSo!$B$23*ThamSo!$B$4,IF(ThamSo!$C$23="USD",ThamSo!$B$23*ThamSo!$B$5,ThamSo!$B$23)) -> 3931500 | D8: =B8*C8 -> 3931500 | E8: =D8*$B$2 -> 7863000 | F8: ThamSo dòng vé đi của nhóm
A9: Vé về (Vietjet từ Đại Hưng) | B9: 1 | C9: =IF(ThamSo!$C$26="CNY",ThamSo!$B$26*ThamSo!$B$4,IF(ThamSo!$C$26="USD",ThamSo!$B$26*ThamSo!$B$5,ThamSo!$B$26)) -> 3196000 | D9: =B9*C9 -> 3196000 | E9: =D9*$B$2 -> 6392000 | F9: ThamSo dòng vé về của nhóm
A10: Hành lý ký gửi Vietjet 20 kg | B10: 1 | C10: =IF(ThamSo!$C$28="CNY",ThamSo!$B$28*ThamSo!$B$4,IF(ThamSo!$C$28="USD",ThamSo!$B$28*ThamSo!$B$5,ThamSo!$B$28)) -> 450000 | D10: =B10*C10 -> 450000 | E10: =D10*$B$2 -> 900000 | F10: Về 0 nếu vé đã kèm 20 kg
A11: Bay SZX → HGH | B11: 1 | C11: =IF(ThamSo!$C$29="CNY",ThamSo!$B$29*ThamSo!$B$4,IF(ThamSo!$C$29="USD",ThamSo!$B$29*ThamSo!$B$5,ThamSo!$B$29)) -> 2358150 | D11: =B11*C11 -> 2358150 | E11: =D11*$B$2 -> 4716300 | F11: Eco nội địa kèm 20 kg
A12: Tàu Hangzhou East → Beijing South | B12: 1 | C12: =IF(ThamSo!$C$30="CNY",ThamSo!$B$30*ThamSo!$B$4,IF(ThamSo!$C$30="USD",ThamSo!$B$30*ThamSo!$B$5,ThamSo!$B$30)) -> 2054000 | D12: =B12*C12 -> 2054000 | E12: =D12*$B$2 -> 4108000 | F12: Hạng 2
A13: Khách sạn Thâm Quyến | B13: =ThamSo!$B$15 -> 3 | C13: =ThamSo!$C$15*ThamSo!$B$4*$B$3/$B$2 -> 691250 | D13: =B13*C13 -> 2073750 | E13: =D13*$B$2 -> 4147500 | F13: Số đêm × giá phòng × số phòng ÷ số người
A14: Khách sạn Hàng Châu | B14: =ThamSo!$B$16 -> 3 | C14: =ThamSo!$C$16*ThamSo!$B$4*$B$3/$B$2 -> 750500 | D14: =B14*C14 -> 2251500 | E14: =D14*$B$2 -> 4503000 | F14: Số đêm × giá phòng × số phòng ÷ số người
A15: Khách sạn Bắc Kinh | B15: =ThamSo!$B$17 -> 4 | C15: =ThamSo!$C$17*ThamSo!$B$4*$B$3/$B$2 -> 790000 | D15: =B15*C15 -> 3160000 | E15: =D15*$B$2 -> 6320000 | F15: Số đêm × giá phòng × số phòng ÷ số người
A16: Vé tham quan (theo bảng ThamSo) | B16: 1 | C16: =ThamSo!$B$50*ThamSo!$B$4 -> 4285750 | D16: =B16*C16 -> 4285750 | E16: =D16*$B$2 -> 8571500 | F16: Chỉ tính dòng có cột 'Tính' = 1
A17: Xe 14 chỗ ngày Trường Thành (chia đều) | B17: 1 | C17: =ThamSo!$B$53*ThamSo!$B$4/ThamSo!$B$12 -> 592500 | D17: =B17*C17 -> 592500 | E17: =D17*$B$2 -> 1185000 | F17: Cả xe ÷ tổng số người cả đoàn
A18: Đi lại nội thành | B18: =ThamSo!$B$19 -> 11 | C18: =ThamSo!$B$54*ThamSo!$B$4 -> 237000 | D18: =B18*C18 -> 2607000 | E18: =D18*$B$2 -> 5214000 | F18: Số ngày tour × đơn giá/ngày
A19: Transfer sân bay, ga | B19: 1 | C19: =ThamSo!$B$55*ThamSo!$B$4 -> 592500 | D19: =B19*C19 -> 592500 | E19: =D19*$B$2 -> 1185000 | F19: Cả chuyến
A20: Ăn uống | B20: =ThamSo!$B$19 -> 11 | C20: =ThamSo!$B$56*ThamSo!$B$4 -> 711000 | D20: =B20*C20 -> 7821000 | E20: =D20*$B$2 -> 15642000 | F20: Số ngày tour × đơn giá/ngày
A21: eSIM | B21: 1 | C21: =ThamSo!$B$57*ThamSo!$B$5 -> 445570 | D21: =B21*C21 -> 445570 | E21: =D21*$B$2 -> 891140 | F21: 10 ngày
A22: Bảo hiểm du lịch | B22: 1 | C22: =ThamSo!$B$58 -> 0 | D22: =B22*C22 -> 0 | E22: =D22*$B$2 -> 0 | F22: Tuỳ chọn
A23: TỔNG (chưa dự phòng) | D23: =SUM(D7:D22) | E23: =SUM(E7:E22) -> 76153640 | F23: Chưa gồm mua sắm
A24: Dự phòng | D24: =D23*ThamSo!$B$6 -> 3807682 | E24: =E23*ThamSo!$B$6 -> 7615364 | F24: Tỷ lệ ở ThamSo!B6
A25: TỔNG CÓ DỰ PHÒNG | D25: =D23+D24 -> 41884502 | E25: =E23+E24 -> 83769004

Sheet ChiPhi_SGN
A1: CHI PHÍ DỰ KIẾN – nhóm SGN (VND). Toàn bộ là công thức, sửa ở sheet ThamSo.
A2: Số người | B2: =ThamSo!$B$10 -> 4
A3: Số phòng | B3: =ThamSo!$C$10 -> 2
A4: Cần visa (1/0) | B4: =ThamSo!$D$10 -> 1
A6: Khoản | B6: Số lượng | C6: Đơn giá (VND) | D6: Thành tiền / người (VND) | E6: Cả nhóm (VND) | F6: Cách tính / ghi chú
A7: Visa Trung Quốc loại L | B7: =$B$4 -> 1 | C7: =ThamSo!$B$59*ThamSo!$B$5+ThamSo!$B$60 -> 2257600 | D7: =B7*C7 -> 2257600 | E7: =D7*$B$2 -> 9030400 | F7: Phí lãnh sự (USD) + phí dịch vụ CVASC; = 0 nếu nhóm không cần visa
A8: Vé đi (tới Thâm Quyến) | B8: 1 | C8: =IF(ThamSo!$C$24="CNY",ThamSo!$B$24*ThamSo!$B$4,IF(ThamSo!$C$24="USD",ThamSo!$B$24*ThamSo!$B$5,ThamSo!$B$24)) -> 1913330 | D8: =B8*C8 -> 1913330 | E8: =D8*$B$2 -> 7653320 | F8: ThamSo dòng vé đi của nhóm
A9: Vé về (Vietjet từ Đại Hưng) | B9: 1 | C9: =IF(ThamSo!$C$27="CNY",ThamSo!$B$27*ThamSo!$B$4,IF(ThamSo!$C$27="USD",ThamSo!$B$27*ThamSo!$B$5,ThamSo!$B$27)) -> 4164000 | D9: =B9*C9 -> 4164000 | E9: =D9*$B$2 -> 16656000 | F9: ThamSo dòng vé về của nhóm
A10: Hành lý ký gửi Vietjet 20 kg | B10: 1 | C10: =IF(ThamSo!$C$28="CNY",ThamSo!$B$28*ThamSo!$B$4,IF(ThamSo!$C$28="USD",ThamSo!$B$28*ThamSo!$B$5,ThamSo!$B$28)) -> 450000 | D10: =B10*C10 -> 450000 | E10: =D10*$B$2 -> 1800000 | F10: Về 0 nếu vé đã kèm 20 kg
A11: Bay SZX → HGH | B11: 1 | C11: =IF(ThamSo!$C$29="CNY",ThamSo!$B$29*ThamSo!$B$4,IF(ThamSo!$C$29="USD",ThamSo!$B$29*ThamSo!$B$5,ThamSo!$B$29)) -> 2358150 | D11: =B11*C11 -> 2358150 | E11: =D11*$B$2 -> 9432600 | F11: Eco nội địa kèm 20 kg
A12: Tàu Hangzhou East → Beijing South | B12: 1 | C12: =IF(ThamSo!$C$30="CNY",ThamSo!$B$30*ThamSo!$B$4,IF(ThamSo!$C$30="USD",ThamSo!$B$30*ThamSo!$B$5,ThamSo!$B$30)) -> 2054000 | D12: =B12*C12 -> 2054000 | E12: =D12*$B$2 -> 8216000 | F12: Hạng 2
A13: Khách sạn Thâm Quyến | B13: =ThamSo!$B$15 -> 3 | C13: =ThamSo!$C$15*ThamSo!$B$4*$B$3/$B$2 -> 691250 | D13: =B13*C13 -> 2073750 | E13: =D13*$B$2 -> 8295000 | F13: Số đêm × giá phòng × số phòng ÷ số người
A14: Khách sạn Hàng Châu | B14: =ThamSo!$B$16 -> 3 | C14: =ThamSo!$C$16*ThamSo!$B$4*$B$3/$B$2 -> 750500 | D14: =B14*C14 -> 2251500 | E14: =D14*$B$2 -> 9006000 | F14: Số đêm × giá phòng × số phòng ÷ số người
A15: Khách sạn Bắc Kinh | B15: =ThamSo!$B$17 -> 4 | C15: =ThamSo!$C$17*ThamSo!$B$4*$B$3/$B$2 -> 790000 | D15: =B15*C15 -> 3160000 | E15: =D15*$B$2 -> 12640000 | F15: Số đêm × giá phòng × số phòng ÷ số người
A16: Vé tham quan (theo bảng ThamSo) | B16: 1 | C16: =ThamSo!$B$50*ThamSo!$B$4 -> 4285750 | D16: =B16*C16 -> 4285750 | E16: =D16*$B$2 -> 17143000 | F16: Chỉ tính dòng có cột 'Tính' = 1
A17: Xe 14 chỗ ngày Trường Thành (chia đều) | B17: 1 | C17: =ThamSo!$B$53*ThamSo!$B$4/ThamSo!$B$12 -> 592500 | D17: =B17*C17 -> 592500 | E17: =D17*$B$2 -> 2370000 | F17: Cả xe ÷ tổng số người cả đoàn
A18: Đi lại nội thành | B18: =ThamSo!$B$19 -> 11 | C18: =ThamSo!$B$54*ThamSo!$B$4 -> 237000 | D18: =B18*C18 -> 2607000 | E18: =D18*$B$2 -> 10428000 | F18: Số ngày tour × đơn giá/ngày
A19: Transfer sân bay, ga | B19: 1 | C19: =ThamSo!$B$55*ThamSo!$B$4 -> 592500 | D19: =B19*C19 -> 592500 | E19: =D19*$B$2 -> 2370000 | F19: Cả chuyến
A20: Ăn uống | B20: =ThamSo!$B$19 -> 11 | C20: =ThamSo!$B$56*ThamSo!$B$4 -> 711000 | D20: =B20*C20 -> 7821000 | E20: =D20*$B$2 -> 31284000 | F20: Số ngày tour × đơn giá/ngày
A21: eSIM | B21: 1 | C21: =ThamSo!$B$57*ThamSo!$B$5 -> 445570 | D21: =B21*C21 -> 445570 | E21: =D21*$B$2 -> 1782280 | F21: 10 ngày
A22: Bảo hiểm du lịch | B22: 1 | C22: =ThamSo!$B$58 -> 0 | D22: =B22*C22 -> 0 | E22: =D22*$B$2 -> 0 | F22: Tuỳ chọn
A23: TỔNG (chưa dự phòng) | D23: =SUM(D7:D22) | E23: =SUM(E7:E22) -> 148106600 | F23: Chưa gồm mua sắm
A24: Dự phòng | D24: =D23*ThamSo!$B$6 -> 3702665 | E24: =E23*ThamSo!$B$6 -> 14810660 | F24: Tỷ lệ ở ThamSo!B6
A25: TỔNG CÓ DỰ PHÒNG | D25: =D23+D24 -> 40729315 | E25: =E23+E24 -> 162917260

Sheet ChiPhi_QC
A1: CHI PHÍ DỰ KIẾN – nhóm QC (VND). Toàn bộ là công thức, sửa ở sheet ThamSo.
A2: Số người | B2: =ThamSo!$B$11 -> 2
A3: Số phòng | B3: =ThamSo!$C$11 -> 1
A4: Cần visa (1/0) | B4: =ThamSo!$D$11 -> 1
A6: Khoản | B6: Số lượng | C6: Đơn giá (VND) | D6: Thành tiền / người (VND) | E6: Cả nhóm (VND) | F6: Cách tính / ghi chú
A7: Visa Trung Quốc loại L | B7: =$B$4 -> 1 | C7: =ThamSo!$B$59*ThamSo!$B$5+ThamSo!$B$60 -> 2257600 | D7: =B7*C7 -> 2257600 | E7: =D7*$B$2 -> 4515200 | F7: Phí lãnh sự (USD) + phí dịch vụ CVASC; = 0 nếu nhóm không cần visa
A8: Vé đi (tới Thâm Quyến) | B8: 1 | C8: =IF(ThamSo!$C$25="CNY",ThamSo!$B$25*ThamSo!$B$4,IF(ThamSo!$C$25="USD",ThamSo!$B$25*ThamSo!$B$5,ThamSo!$B$25)) -> 294275 | D8: =B8*C8 -> 294275 | E8: =D8*$B$2 -> 588550 | F8: ThamSo dòng vé đi của nhóm
A9: Vé về (Vietjet từ Đại Hưng) | B9: 1 | C9: =IF(ThamSo!$C$27="CNY",ThamSo!$B$27*ThamSo!$B$4,IF(ThamSo!$C$27="USD",ThamSo!$B$27*ThamSo!$B$5,ThamSo!$B$27)) -> 4164000 | D9: =B9*C9 -> 4164000 | E9: =D9*$B$2 -> 8328000 | F9: ThamSo dòng vé về của nhóm
A10: Hành lý ký gửi Vietjet 20 kg | B10: 1 | C10: =IF(ThamSo!$C$28="CNY",ThamSo!$B$28*ThamSo!$B$4,IF(ThamSo!$C$28="USD",ThamSo!$B$28*ThamSo!$B$5,ThamSo!$B$28)) -> 450000 | D10: =B10*C10 -> 450000 | E10: =D10*$B$2 -> 900000 | F10: Về 0 nếu vé đã kèm 20 kg
A11: Bay SZX → HGH | B11: 1 | C11: =IF(ThamSo!$C$29="CNY",ThamSo!$B$29*ThamSo!$B$4,IF(ThamSo!$C$29="USD",ThamSo!$B$29*ThamSo!$B$5,ThamSo!$B$29)) -> 2358150 | D11: =B11*C11 -> 2358150 | E11: =D11*$B$2 -> 4716300 | F11: Eco nội địa kèm 20 kg
A12: Tàu Hangzhou East → Beijing South | B12: 1 | C12: =IF(ThamSo!$C$30="CNY",ThamSo!$B$30*ThamSo!$B$4,IF(ThamSo!$C$30="USD",ThamSo!$B$30*ThamSo!$B$5,ThamSo!$B$30)) -> 2054000 | D12: =B12*C12 -> 2054000 | E12: =D12*$B$2 -> 4108000 | F12: Hạng 2
A13: Khách sạn Thâm Quyến | B13: =ThamSo!$B$15 -> 3 | C13: =ThamSo!$C$15*ThamSo!$B$4*$B$3/$B$2 -> 691250 | D13: =B13*C13 -> 2073750 | E13: =D13*$B$2 -> 4147500 | F13: Số đêm × giá phòng × số phòng ÷ số người
A14: Khách sạn Hàng Châu | B14: =ThamSo!$B$16 -> 3 | C14: =ThamSo!$C$16*ThamSo!$B$4*$B$3/$B$2 -> 750500 | D14: =B14*C14 -> 2251500 | E14: =D14*$B$2 -> 4503000 | F14: Số đêm × giá phòng × số phòng ÷ số người
A15: Khách sạn Bắc Kinh | B15: =ThamSo!$B$17 -> 4 | C15: =ThamSo!$C$17*ThamSo!$B$4*$B$3/$B$2 -> 790000 | D15: =B15*C15 -> 3160000 | E15: =D15*$B$2 -> 6320000 | F15: Số đêm × giá phòng × số phòng ÷ số người
A16: Vé tham quan (theo bảng ThamSo) | B16: 1 | C16: =ThamSo!$B$50*ThamSo!$B$4 -> 4285750 | D16: =B16*C16 -> 4285750 | E16: =D16*$B$2 -> 8571500 | F16: Chỉ tính dòng có cột 'Tính' = 1
A17: Xe 14 chỗ ngày Trường Thành (chia đều) | B17: 1 | C17: =ThamSo!$B$53*ThamSo!$B$4/ThamSo!$B$12 -> 592500 | D17: =B17*C17 -> 592500 | E17: =D17*$B$2 -> 1185000 | F17: Cả xe ÷ tổng số người cả đoàn
A18: Đi lại nội thành | B18: =ThamSo!$B$19 -> 11 | C18: =ThamSo!$B$54*ThamSo!$B$4 -> 237000 | D18: =B18*C18 -> 2607000 | E18: =D18*$B$2 -> 5214000 | F18: Số ngày tour × đơn giá/ngày
A19: Transfer sân bay, ga | B19: 1 | C19: =ThamSo!$B$55*ThamSo!$B$4 -> 592500 | D19: =B19*C19 -> 592500 | E19: =D19*$B$2 -> 1185000 | F19: Cả chuyến
A20: Ăn uống | B20: =ThamSo!$B$19 -> 11 | C20: =ThamSo!$B$56*ThamSo!$B$4 -> 711000 | D20: =B20*C20 -> 7821000 | E20: =D20*$B$2 -> 15642000 | F20: Số ngày tour × đơn giá/ngày
A21: eSIM | B21: 1 | C21: =ThamSo!$B$57*ThamSo!$B$5 -> 445570 | D21: =B21*C21 -> 445570 | E21: =D21*$B$2 -> 891140 | F21: 10 ngày
A22: Bảo hiểm du lịch | B22: 1 | C22: =ThamSo!$B$58 -> 0 | D22: =B22*C22 -> 0 | E22: =D22*$B$2 -> 0 | F22: Tuỳ chọn
A23: TỔNG (chưa dự phòng) | D23: =SUM(D7:D22) | E23: =SUM(E7:E22) -> 70815190 | F23: Chưa gồm mua sắm
A24: Dự phòng | D24: =D23*ThamSo!$B$6 -> 3540759.5 | E24: =E23*ThamSo!$B$6 -> 7081519 | F24: Tỷ lệ ở ThamSo!B6
A25: TỔNG CÓ DỰ PHÒNG | D25: =D23+D24 -> 38948354 | E25: =E23+E24 -> 77896709

Sheet Nguon
A1: NGUỒN THAM KHẢO (tra 21/09/2026)
A4: Tỷ giá CNY/VND VCB 19/09/2026 | B4: https://baohatinh.vn/cong-cu/ty-gia/cny
A5: Tỷ giá USD/VND VCB 20/09/2026 | B5: https://chogia.vn/ty-gia/vietcombank/
A6: Phí visa TQ 2026 | B6: https://mia.vn/cam-nang-du-lich/lam-visa-du-lich-trung-quoc-het-bao-nhieu-tien-20201
A7: Visa TQ cho công dân VN, CVASC | B7: https://chinatravelflow.com/en/visa/china-visa-for-vietnamese-citizens
A8: Skyscanner SGN–SZX (từ 113 USD) | B8: https://www.skyscanner.com/routes/sgn/szx/ho-chi-minh-city-to-shenzhen-bao-an-international.html
A9: Đại lý China Southern VN (khứ hồi 5,3–8,5 triệu) | B9: https://chinasouthernair.vn/ve-may-bay-di-trung-quoc
A10: Expedia HAN–SZX (từ 144 USD, TB 142 USD) | B10: https://www.expedia.com/lp/flights/han/szx/hanoi-to-shenzhen
A11: Airportia CZ8466 | B11: https://www.airportia.com/flights/cz8466/ho-chi-minh-city/shenzhen/
A12: Shenzhen Airlines timetable 12/2025 (ZH104) | B12: https://globalpage.shenzhenair.com/webfile/zhair/cms/static/pages/wcm/static-navigation/Itinerary/FAQ/schedule/flight_timetable/FlightTimetable%2020251216.pdf
A13: VJ7713 lịch 2026 (01:20, từ 103 USD) | B13: https://www.trip.com/flights/status-vj7713/
A14: Airportia VJ3949 | B14: https://www.airportia.com/flights/vj3949/beijing/ho-chi-minh-city/
A15: Vietjet tặng 20 kg quốc tế 2026 | B15: https://www.ivivu.com/blog/2026/03/vietjet-air-tang-20kg-hanh-ly-ky-gui-cho-cac-chuyen-bay-quoc-te/
... A44: eSIM TQ 2026 | B44: https://unusualnomad.com/china-esim/
